<?xml version="1.0" ?>
<!-- =================================================================================== -->
<!-- |    This document was autogenerated by xacro from raw3-1.urdf.xacro              | -->
<!-- |    EDITING THIS FILE BY HAND IS NOT RECOMMENDED                                 | -->
<!-- =================================================================================== -->
<robot name="raw3-1" xmlns:xacro="http://www.ros.org/wiki/xacro">
  <!-- common stuff -->
  <!-- geometry macros for modeling geometric primitives with according meshes -->
  <!-- see https://secure.wikimedia.org/wikipedia/en/wiki/List_of_moment_of_inertia_tensors -->
  <material name="IPA/LightGrey">
    <color rgba="0.7 0.7 0.7 1.0"/>
  </material>
  <material name="IPA/DarkGrey">
    <color rgba="0.4 0.4 0.4 1.0"/>
  </material>
  <material name="IPA/Black">
    <color rgba="0.0 0.0 0.0 1.0"/>
  </material>
  <material name="IPA/Metall">
    <color rgba="0.7 0.7 0.7 1.0"/>
  </material>
  <material name="IPA/YellowRubber">
    <color rgba="0.4 0.27 0.16 1.0"/>
  </material>
  <material name="IPA/Orange">
    <color rgba="1.0 0.4 0.0 1.0"/>
  </material>
  <material name="IPA/Blue">
    <color rgba="0.0 0.0 0.5 1.0"/>
  </material>
  <!-- ***************** -->
  <!-- base calibration -->
  <!-- ***************** -->
  <!-- laser front mount positions | relative to base_link -->
  <!-- laser rear mount positions | relative to base_link -->
  <!-- *********************************** -->
  <!-- kinematic chain reference positions -->
  <!-- *********************************** -->
  <!-- tower mount positions | relative to base_link -->
  <!--torso mount positions | relative to base_link-->
  <!-- head mount positions | relative to head_cover_link -->
  <!--arm mount positions | relative to base_link-->
  <!-- 0.565 -->
  <!-- gripper mount positions | relative to arm_ee_link -->
  <!-- ***************************** -->
  <!-- camera calibration properties -->
  <!-- ***************************** -->
  <!-- left | handeye calibration | relative to head_axis_link -->
  <!-- left | handeye calibration | relative to cam_reference_link -->
  <!-- right | stereo baseline calibration | relative to cam_reference_link -->
  <!-- cam3d | handeye calibration | relative to cam_reference_link -->
  <!-- ***************** -->
  <!-- base calibration -->
  <!-- ***************** -->
  <!-- laser front mount positions | relative to base_link -->
  <!-- laser rear mount positions | relative to base_link -->
  <!-- *********************** -->
  <!-- upper robot calibration -->
  <!-- *********************** -->
  <!-- tower mount positions | relative to base_link -->
  <!-- torso mount positions | relative to base_link -->
  <!-- head mount positions | relative to head_cover_link -->
  <!-- arm mount positions | relative to base_link -->
  <!-- gripper mount positions | relative to arm_ee_link -->
  <!-- ***************************** -->
  <!-- camera calibration properties -->
  <!-- ***************************** -->
  <!-- left | handeye calibration | relative to head_axis_link -->
  <!-- left | handeye calibration | relative to cam_reference_link -->
  <!-- right | stereo baseline calibration | relative to cam_reference_link -->
  <!-- cam3d | handeye calibration | relative to cam_reference_link -->
  &gt;

	
  <!-- ***************** -->
  <!-- base calibration -->
  <!-- ***************** -->
  <!-- laser front mount positions | relative to base_link -->
  <!-- laser rear mount positions | relative to base_link -->
  <!-- *********************** -->
  <!-- upper robot calibration -->
  <!-- *********************** -->
  <!-- tower mount positions | relative to base_link -->
  <!-- torso mount positions | relative to base_link -->
  <!-- head mount positions | relative to head_cover_link -->
  <!-- arm mount positions | relative to base_link -->
  <!-- gripper mount positions | relative to arm_ee_link -->
  <!-- ***************************** -->
  <!-- camera calibration properties -->
  <!-- ***************************** -->
  <!-- left | handeye calibration | relative to head_axis_link -->
  <!-- left | handeye calibration | relative to cam_reference_link -->
  <!-- right | stereo baseline calibration | relative to cam_reference_link -->
  <!-- cam3d | handeye calibration | relative to cam_reference_link -->
  <!-- raw base -->
  <!-- geometry macros for modeling geometric primitives with according meshes -->
  <!-- see https://secure.wikimedia.org/wikipedia/en/wiki/List_of_moment_of_inertia_tensors -->
  <!-- drive_wheel module -->
  <!--  Caster wheel transmission   -->
  <!-- Hub transmission only -->
  <!-- Macro for Caster hub only -->
  <!-- sensors -->
  <!--simple collision model for the laser -->
  <!-- properties -->
  <!--modify here-->
  <!-- battery macros-->
  <!-- raw tower -->
  <!--xacro:include filename="$(find raw_description)/urdf/tower_asymetric/tower.urdf.xacro" /-->
  <!-- Properties -->
  <!-- torso -->
  <!-- head -->
  <!-- ur_arm -->
  <!-- geometry macros for modeling geometric primitives with according meshes -->
  <!-- see https://secure.wikimedia.org/wikipedia/en/wiki/List_of_moment_of_inertia_tensors -->
  <!--
  Author: Kelsey Hawkins 
  Contributers: Jimmy Da Silva, Ajit Krisshna N L, Muhammad Asif Rana 
-->
  <!-- Inertia parameters -->
  <!-- This mass might be incorrect -->
  <!-- These parameters are borrowed from the urcontrol.conf file
       but are not verified for the correct permutation.
       The permutation was guessed by looking at the UR5 parameters.
       Serious use of these parameters needs further inspection. -->
  <!-- Kinematic model -->
  <!-- Properties from urcontrol.conf -->
  <!-- Arbitrary offsets for shoulder/elbow joints -->
  <!-- measured from model -->
  <!-- measured from model -->
  <!-- link lengths used in model -->
  <!--property name="wrist_3_length" value="0.0857" /-->
  <!-- raw boxgripper 
  <xacro:include filename="$(find raw_description)/urdf/boxgripper/boxgripper.urdf.xacro" /> -->
  <!-- gripper -->
  <!-- composition of the robot -->
  <link name="base_footprint"/>
  <joint name="base_footprint_joint" type="fixed">
    <origin rpy="0 0 0" xyz="0 0 0"/>
    <parent link="base_footprint"/>
    <child link="base_link"/>
  </joint>
  <link name="base_link">
    <inertial>
      <origin xyz="0 0 0"/>
      <mass value="0.4"/>
      <inertia ixx="9.64" ixy="-0.02" ixz="0.44" iyy="11.33" iyz="-0.007" izz="3.07"/>
    </inertial>
    <visual>
      <origin rpy="0 0 0" xyz="0 0 0.209"/>
      <geometry>
        <mesh filename="package://raw_description/meshes/base/raw_base_long.dae"/>
      </geometry>
    </visual>
    <collision>
      <origin rpy="0 0 0" xyz="0 0 0.209"/>
      <geometry>
        <mesh filename="package://raw_description/meshes/base/raw_base_long.stl"/>
        <!--box size="1.04 0.58 0.31" /-->
      </geometry>
    </collision>
  </link>
  <!-- arrangement of the four drive_wheel modules -->
  <joint name="fl_caster_rotation_joint" type="continuous">
    <origin rpy="0 0 0" xyz="0.368 0.184 0.09"/>
    <parent link="base_link"/>
    <child link="fl_caster_rotation_link"/>
    <axis xyz="0 0 1"/>
    <limit effort="100" velocity="100"/>
    <!-- alpha tested velocity and effort limits -->
    <safety_controller k_velocity="10"/>
    <dynamics damping="0.0" friction="0.0"/>
  </joint>
  <link name="fl_caster_rotation_link">
    <inertial>
      <origin xyz="0 0 0"/>
      <mass value="5.9"/>
      <inertia ixx="0.04" ixy="-0.0007" ixz="0.0" iyy="0.02" iyz="-0.000004" izz="0.05"/>
    </inertial>
    <visual>
      <geometry>
        <mesh filename="package://cob_description/meshes/drive_wheel/caster.stl"/>
      </geometry>
      <material name="IPA/LightGrey"/>
    </visual>
    <collision>
      <geometry>
        <box size="0.001 0.001 0.001"/>
      </geometry>
    </collision>
  </link>
  <!-- extensions -->
  <transmission name="fl_caster_rotation_trans">
    <type>transmission_interface/SimpleTransmission</type>
    <joint name="fl_caster_rotation_joint">
      <hardwareInterface>VelocityJointInterface</hardwareInterface>
    </joint>
    <actuator name="fl_caster_rotation_motor">
      <mechanicalReduction>-79.2380952381</mechanicalReduction>
    </actuator>
  </transmission>
  <joint name="fl_caster_r_wheel_joint" type="continuous">
    <origin rpy="0 0 0" xyz="0 -0.0 0"/>
    <parent link="fl_caster_rotation_link"/>
    <child link="fl_caster_r_wheel_link"/>
    <axis xyz="0 1 0"/>
    <limit effort="100" velocity="100"/>
    <!-- alpha tested effort and velocity limits -->
    <safety_controller k_velocity="10"/>
    <dynamics damping="0.0" friction="0.0"/>
  </joint>
  <link name="fl_caster_r_wheel_link">
    <inertial>
      <origin xyz="0 0 0"/>
      <mass value="0.44036"/>
      <inertia ixx="0.012411765597" ixy="-0.000711733678" ixz="0.00050272983" iyy="0.015218160428" iyz="-0.000004273467" izz="0.011763977943"/>
    </inertial>
    <visual>
      <geometry>
        <mesh filename="package://cob_description/meshes/drive_wheel/wheel.dae"/>
      </geometry>
    </visual>
    <collision>
      <geometry>
        <mesh filename="package://cob_description/meshes/drive_wheel/wheel.stl"/>
      </geometry>
    </collision>
  </link>
  <!-- extensions -->
  <gazebo reference="fl_caster_r_wheel_link">
    <gravity>true</gravity>
    <self_collide>false</self_collide>
  </gazebo>
  <transmission name="fl_caster_r_wheel_trans">
    <type>transmission_interface/SimpleTransmission</type>
    <joint name="fl_caster_r_wheel_joint">
      <hardwareInterface>VelocityJointInterface</hardwareInterface>
    </joint>
    <actuator name="fl_caster_r_wheel_motor">
      <mechanicalReduction>-79.2380952381</mechanicalReduction>
    </actuator>
  </transmission>
  <!-- extensions -->
  <gazebo reference="fl_caster_rotation_link">
    <gravity>true</gravity>
    <self_collide>false</self_collide>
    <material value="IPA/Metal"/>
  </gazebo>
  <joint name="fr_caster_rotation_joint" type="continuous">
    <origin rpy="0 0 0" xyz="0.368 -0.134 0.09"/>
    <parent link="base_link"/>
    <child link="fr_caster_rotation_link"/>
    <axis xyz="0 0 1"/>
    <limit effort="100" velocity="100"/>
    <!-- alpha tested velocity and effort limits -->
    <safety_controller k_velocity="10"/>
    <dynamics damping="0.0" friction="0.0"/>
  </joint>
  <link name="fr_caster_rotation_link">
    <inertial>
      <origin xyz="0 0 0"/>
      <mass value="5.9"/>
      <inertia ixx="0.04" ixy="-0.0007" ixz="0.0" iyy="0.02" iyz="-0.000004" izz="0.05"/>
    </inertial>
    <visual>
      <geometry>
        <mesh filename="package://cob_description/meshes/drive_wheel/caster.stl"/>
      </geometry>
      <material name="IPA/LightGrey"/>
    </visual>
    <collision>
      <geometry>
        <box size="0.001 0.001 0.001"/>
      </geometry>
    </collision>
  </link>
  <!-- extensions -->
  <transmission name="fr_caster_rotation_trans">
    <type>transmission_interface/SimpleTransmission</type>
    <joint name="fr_caster_rotation_joint">
      <hardwareInterface>VelocityJointInterface</hardwareInterface>
    </joint>
    <actuator name="fr_caster_rotation_motor">
      <mechanicalReduction>-79.2380952381</mechanicalReduction>
    </actuator>
  </transmission>
  <joint name="fr_caster_r_wheel_joint" type="continuous">
    <origin rpy="0 0 0" xyz="0 -0.0 0"/>
    <parent link="fr_caster_rotation_link"/>
    <child link="fr_caster_r_wheel_link"/>
    <axis xyz="0 1 0"/>
    <limit effort="100" velocity="100"/>
    <!-- alpha tested effort and velocity limits -->
    <safety_controller k_velocity="10"/>
    <dynamics damping="0.0" friction="0.0"/>
  </joint>
  <link name="fr_caster_r_wheel_link">
    <inertial>
      <origin xyz="0 0 0"/>
      <mass value="0.44036"/>
      <inertia ixx="0.012411765597" ixy="-0.000711733678" ixz="0.00050272983" iyy="0.015218160428" iyz="-0.000004273467" izz="0.011763977943"/>
    </inertial>
    <visual>
      <geometry>
        <mesh filename="package://cob_description/meshes/drive_wheel/wheel.dae"/>
      </geometry>
    </visual>
    <collision>
      <geometry>
        <mesh filename="package://cob_description/meshes/drive_wheel/wheel.stl"/>
      </geometry>
    </collision>
  </link>
  <!-- extensions -->
  <gazebo reference="fr_caster_r_wheel_link">
    <gravity>true</gravity>
    <self_collide>false</self_collide>
  </gazebo>
  <transmission name="fr_caster_r_wheel_trans">
    <type>transmission_interface/SimpleTransmission</type>
    <joint name="fr_caster_r_wheel_joint">
      <hardwareInterface>VelocityJointInterface</hardwareInterface>
    </joint>
    <actuator name="fr_caster_r_wheel_motor">
      <mechanicalReduction>-79.2380952381</mechanicalReduction>
    </actuator>
  </transmission>
  <!-- extensions -->
  <gazebo reference="fr_caster_rotation_link">
    <gravity>true</gravity>
    <self_collide>false</self_collide>
    <material value="IPA/Metal"/>
  </gazebo>
  <joint name="bl_caster_rotation_joint" type="continuous">
    <origin rpy=" 0 0 0" xyz="-0.368 0.134 0.09"/>
    <parent link="base_link"/>
    <child link="bl_caster_rotation_link"/>
    <axis xyz="0 0 1"/>
    <limit effort="100" velocity="100"/>
    <!-- alpha tested velocity and effort limits -->
    <safety_controller k_velocity="10"/>
    <dynamics damping="0.0" friction="0.0"/>
  </joint>
  <link name="bl_caster_rotation_link">
    <inertial>
      <origin xyz="0 0 0"/>
      <mass value="5.9"/>
      <inertia ixx="0.04" ixy="-0.0007" ixz="0.0" iyy="0.02" iyz="-0.000004" izz="0.05"/>
    </inertial>
    <visual>
      <geometry>
        <mesh filename="package://cob_description/meshes/drive_wheel/caster.stl"/>
      </geometry>
      <material name="IPA/LightGrey"/>
    </visual>
    <collision>
      <geometry>
        <box size="0.001 0.001 0.001"/>
      </geometry>
    </collision>
  </link>
  <!-- extensions -->
  <transmission name="bl_caster_rotation_trans">
    <type>transmission_interface/SimpleTransmission</type>
    <joint name="bl_caster_rotation_joint">
      <hardwareInterface>VelocityJointInterface</hardwareInterface>
    </joint>
    <actuator name="bl_caster_rotation_motor">
      <mechanicalReduction>-79.2380952381</mechanicalReduction>
    </actuator>
  </transmission>
  <joint name="bl_caster_r_wheel_joint" type="continuous">
    <origin rpy="0 0 0" xyz="0 -0.0 0"/>
    <parent link="bl_caster_rotation_link"/>
    <child link="bl_caster_r_wheel_link"/>
    <axis xyz="0 1 0"/>
    <limit effort="100" velocity="100"/>
    <!-- alpha tested effort and velocity limits -->
    <safety_controller k_velocity="10"/>
    <dynamics damping="0.0" friction="0.0"/>
  </joint>
  <link name="bl_caster_r_wheel_link">
    <inertial>
      <origin xyz="0 0 0"/>
      <mass value="0.44036"/>
      <inertia ixx="0.012411765597" ixy="-0.000711733678" ixz="0.00050272983" iyy="0.015218160428" iyz="-0.000004273467" izz="0.011763977943"/>
    </inertial>
    <visual>
      <geometry>
        <mesh filename="package://cob_description/meshes/drive_wheel/wheel.dae"/>
      </geometry>
    </visual>
    <collision>
      <geometry>
        <mesh filename="package://cob_description/meshes/drive_wheel/wheel.stl"/>
      </geometry>
    </collision>
  </link>
  <!-- extensions -->
  <gazebo reference="bl_caster_r_wheel_link">
    <gravity>true</gravity>
    <self_collide>false</self_collide>
  </gazebo>
  <transmission name="bl_caster_r_wheel_trans">
    <type>transmission_interface/SimpleTransmission</type>
    <joint name="bl_caster_r_wheel_joint">
      <hardwareInterface>VelocityJointInterface</hardwareInterface>
    </joint>
    <actuator name="bl_caster_r_wheel_motor">
      <mechanicalReduction>-79.2380952381</mechanicalReduction>
    </actuator>
  </transmission>
  <!-- extensions -->
  <gazebo reference="bl_caster_rotation_link">
    <gravity>true</gravity>
    <self_collide>false</self_collide>
    <material value="IPA/Metal"/>
  </gazebo>
  <joint name="br_caster_rotation_joint" type="continuous">
    <origin rpy="0 0 0" xyz="-0.368 -0.184 0.09"/>
    <parent link="base_link"/>
    <child link="br_caster_rotation_link"/>
    <axis xyz="0 0 1"/>
    <limit effort="100" velocity="100"/>
    <!-- alpha tested velocity and effort limits -->
    <safety_controller k_velocity="10"/>
    <dynamics damping="0.0" friction="0.0"/>
  </joint>
  <link name="br_caster_rotation_link">
    <inertial>
      <origin xyz="0 0 0"/>
      <mass value="5.9"/>
      <inertia ixx="0.04" ixy="-0.0007" ixz="0.0" iyy="0.02" iyz="-0.000004" izz="0.05"/>
    </inertial>
    <visual>
      <geometry>
        <mesh filename="package://cob_description/meshes/drive_wheel/caster.stl"/>
      </geometry>
      <material name="IPA/LightGrey"/>
    </visual>
    <collision>
      <geometry>
        <box size="0.001 0.001 0.001"/>
      </geometry>
    </collision>
  </link>
  <!-- extensions -->
  <transmission name="br_caster_rotation_trans">
    <type>transmission_interface/SimpleTransmission</type>
    <joint name="br_caster_rotation_joint">
      <hardwareInterface>VelocityJointInterface</hardwareInterface>
    </joint>
    <actuator name="br_caster_rotation_motor">
      <mechanicalReduction>-79.2380952381</mechanicalReduction>
    </actuator>
  </transmission>
  <joint name="br_caster_r_wheel_joint" type="continuous">
    <origin rpy="0 0 0" xyz="0 -0.0 0"/>
    <parent link="br_caster_rotation_link"/>
    <child link="br_caster_r_wheel_link"/>
    <axis xyz="0 1 0"/>
    <limit effort="100" velocity="100"/>
    <!-- alpha tested effort and velocity limits -->
    <safety_controller k_velocity="10"/>
    <dynamics damping="0.0" friction="0.0"/>
  </joint>
  <link name="br_caster_r_wheel_link">
    <inertial>
      <origin xyz="0 0 0"/>
      <mass value="0.44036"/>
      <inertia ixx="0.012411765597" ixy="-0.000711733678" ixz="0.00050272983" iyy="0.015218160428" iyz="-0.000004273467" izz="0.011763977943"/>
    </inertial>
    <visual>
      <geometry>
        <mesh filename="package://cob_description/meshes/drive_wheel/wheel.dae"/>
      </geometry>
    </visual>
    <collision>
      <geometry>
        <mesh filename="package://cob_description/meshes/drive_wheel/wheel.stl"/>
      </geometry>
    </collision>
  </link>
  <!-- extensions -->
  <gazebo reference="br_caster_r_wheel_link">
    <gravity>true</gravity>
    <self_collide>false</self_collide>
  </gazebo>
  <transmission name="br_caster_r_wheel_trans">
    <type>transmission_interface/SimpleTransmission</type>
    <joint name="br_caster_r_wheel_joint">
      <hardwareInterface>VelocityJointInterface</hardwareInterface>
    </joint>
    <actuator name="br_caster_r_wheel_motor">
      <mechanicalReduction>-79.2380952381</mechanicalReduction>
    </actuator>
  </transmission>
  <!-- extensions -->
  <gazebo reference="br_caster_rotation_link">
    <gravity>true</gravity>
    <self_collide>false</self_collide>
    <material value="IPA/Metal"/>
  </gazebo>
  <!-- base laser front -->
  <joint name="base_laser_front_joint" type="fixed">
    <axis xyz="0 1 0"/>
    <origin rpy="3.14159265359 0.0 -0.785398163397" xyz="0.465 -0.232 0.178"/>
    <parent link="base_link"/>
    <child link="base_laser_front_link"/>
  </joint>
  <link name="base_laser_front_link" type="laser">
    <inertial>
      <mass value="1.2"/>
      <origin rpy="0 0 0" xyz="0 0 0"/>
      <inertia ixx="0.0029999988" ixy="0.0" ixz="0.0" iyy="0.0029999988" iyz="0.0" izz="0.0015"/>
    </inertial>
    <visual>
      <origin rpy="0 0 0" xyz="0 0 0"/>
      <geometry>
        <mesh filename="package://cob_description/meshes/sensors/sick_s300_laser.dae"/>
        <!--box size="0.001 0.001 0.001" /-->
      </geometry>
      <material name="IPA/LightGrey"/>
    </visual>
    <collision>
      <origin rpy="0 0 0" xyz="0 0 0"/>
      <geometry>
        <mesh filename="package://cob_description/meshes/sensors/sick_s300_laser_collision.stl"/>
      </geometry>
    </collision>
  </link>
  <!-- gazebo extensions -->
  <gazebo reference="base_laser_front_link">
    <sensor name="base_laser_front" type="ray">
      <always_on>true</always_on>
      <update_rate>12.0</update_rate>
      <pose>0 0 0 0 0 0</pose>
      <visualize>false</visualize>
      <ray>
        <scan>
          <horizontal>
            <samples>541</samples>
            <resolution>1.0</resolution>
            <min_angle>-2.3562</min_angle>
            <max_angle>2.3562</max_angle>
          </horizontal>
        </scan>
        <range>
          <min>0.05</min>
          <max>30.0</max>
          <resolution>0.03</resolution>
        </range>
        <noise>
          <type>gaussian</type>
          <mean>0.0</mean>
          <stddev>0.005</stddev>
        </noise>
      </ray>
      <plugin filename="libgazebo_ros_laser.so" name="gazebo_ros_base_laser_front_controller">
        <topicName>base_laser_front/scan_raw</topicName>
        <frameName>base_laser_front_link</frameName>
      </plugin>
    </sensor>
  </gazebo>
  <!-- base laser rear -->
  <joint name="base_laser_rear_joint" type="fixed">
    <axis xyz="0 1 0"/>
    <origin rpy="3.14159265359 0.0 -3.92699081699" xyz="-0.465 0.232 0.178"/>
    <parent link="base_link"/>
    <child link="base_laser_rear_link"/>
  </joint>
  <link name="base_laser_rear_link" type="laser">
    <inertial>
      <mass value="1.2"/>
      <origin rpy="0 0 0" xyz="0 0 0"/>
      <inertia ixx="0.0029999988" ixy="0.0" ixz="0.0" iyy="0.0029999988" iyz="0.0" izz="0.0015"/>
    </inertial>
    <visual>
      <origin rpy="0 0 0" xyz="0 0 0"/>
      <geometry>
        <mesh filename="package://cob_description/meshes/sensors/sick_s300_laser.dae"/>
        <!--box size="0.001 0.001 0.001" /-->
      </geometry>
      <material name="IPA/LightGrey"/>
    </visual>
    <collision>
      <origin rpy="0 0 0" xyz="0 0 0"/>
      <geometry>
        <mesh filename="package://cob_description/meshes/sensors/sick_s300_laser_collision.stl"/>
      </geometry>
    </collision>
  </link>
  <!-- gazebo extensions -->
  <gazebo reference="base_laser_rear_link">
    <sensor name="base_laser_rear" type="ray">
      <always_on>true</always_on>
      <update_rate>12.0</update_rate>
      <pose>0 0 0 0 0 0</pose>
      <visualize>false</visualize>
      <ray>
        <scan>
          <horizontal>
            <samples>541</samples>
            <resolution>1.0</resolution>
            <min_angle>-2.3562</min_angle>
            <max_angle>2.3562</max_angle>
          </horizontal>
        </scan>
        <range>
          <min>0.05</min>
          <max>30.0</max>
          <resolution>0.03</resolution>
        </range>
        <noise>
          <type>gaussian</type>
          <mean>0.0</mean>
          <stddev>0.005</stddev>
        </noise>
      </ray>
      <plugin filename="libgazebo_ros_laser.so" name="gazebo_ros_base_laser_rear_controller">
        <topicName>base_laser_rear/scan_raw</topicName>
        <frameName>base_laser_rear_link</frameName>
      </plugin>
    </sensor>
  </gazebo>
  <!-- cam3d -->
  <!--xacro:cob_kinect_v0 name="${name}_cam3d" ros_topic="cam3d" parent="${name}_link">
      <origin xyz="0.51 0.12 0.27" rpy="-${M_PI/2} 0 -${M_PI/2}" />
    </xacro:cob_kinect_v0-->
  <!-- battery front-->
  <joint name="base_battery_front_battery_joint" type="fixed">
    <origin rpy="1.57079632679 0 -1.57079632679" xyz="-0.141 -0.008 0.065"/>
    <parent link="base_link"/>
    <child link="base_battery_front_battery"/>
  </joint>
  <link name="base_battery_front_battery">
    <inertial>
      <mass value="25.0"/>
      <origin rpy="0 0 0" xyz="0 0 0"/>
      <inertia ixx="0.18646659208" ixy="0.0" ixz="0.0" iyy="0.661666402" iyz="0.0" izz="0.56646644008"/>
    </inertial>
    <visual>
      <origin rpy="0 0 0" xyz="0 0 0"/>
      <geometry>
        <mesh filename="package://raw_description/meshes/base/raw_battery.stl"/>
      </geometry>
      <material name="Gazebo/Black"/>
    </visual>
    <collision>
      <origin rpy="0 0 0" xyz="0 0.075 0"/>
      <!-- TODO: Change the origin of the stl, so that collision model doesn't need to be translated  -->
      <geometry>
        <box size="0.5 0.148 0.26"/>
        <!--mesh filename="package://raw_description/meshes/base/raw_battery.stl"/-->
      </geometry>
    </collision>
  </link>
  <!-- extensions -->
  <gazebo reference="base_battery_front_battery">
    <gravity>true</gravity>
    <self_collide>false</self_collide>
    <material value="Gazebo/Black"/>
  </gazebo>
  <!-- battery rear-->
  <joint name="base_battery_rear_battery_joint" type="fixed">
    <origin rpy="1.57079632679 0 -1.57079632679" xyz="0.139 0.007 0.065"/>
    <parent link="base_link"/>
    <child link="base_battery_rear_battery"/>
  </joint>
  <link name="base_battery_rear_battery">
    <inertial>
      <mass value="25.0"/>
      <origin rpy="0 0 0" xyz="0 0 0"/>
      <inertia ixx="0.18646659208" ixy="0.0" ixz="0.0" iyy="0.661666402" iyz="0.0" izz="0.56646644008"/>
    </inertial>
    <visual>
      <origin rpy="0 0 0" xyz="0 0 0"/>
      <geometry>
        <mesh filename="package://raw_description/meshes/base/raw_battery.stl"/>
      </geometry>
      <material name="Gazebo/Black"/>
    </visual>
    <collision>
      <origin rpy="0 0 0" xyz="0 0.075 0"/>
      <!-- TODO: Change the origin of the stl, so that collision model doesn't need to be translated  -->
      <geometry>
        <box size="0.5 0.148 0.26"/>
        <!--mesh filename="package://raw_description/meshes/base/raw_battery.stl"/-->
      </geometry>
    </collision>
  </link>
  <!-- extensions -->
  <gazebo reference="base_battery_rear_battery">
    <gravity>true</gravity>
    <self_collide>false</self_collide>
    <material value="Gazebo/Black"/>
  </gazebo>
  <!-- gazebo extensions -->
  <gazebo reference="base_link">
    <gravity>true</gravity>
    <self_collide>false</self_collide>
    <sensor name="base_contact_sensor" type="contact">
      <always_on>true</always_on>
      <update_rate>100.0</update_rate>
      <contact>
        <collision>base_link_collision</collision>
        <topic>base_bumper</topic>
      </contact>
      <plugin filename="libgazebo_ros_bumper.so" name="base_gazebo_ros_bumper_controller">
        <frameName>world</frameName>
        <bumperTopicName>base_bumper</bumperTopicName>
      </plugin>
    </sensor>
  </gazebo>
  <!--
    <gazebo>
      <plugin name="p3d_base_controller" filename="libgazebo_ros_p3d.so">
        <alwaysOn>true</alwaysOn>
        <updateRate>100.0</updateRate>
        <bodyName>${name}_link</bodyName>
        <topicName>${name}_pose_ground_truth</topicName>
        <frameName>map</frameName>
        <xyzOffsets>25.7 25.7 0</xyzOffsets> 
        <rpyOffsets>0 0 0</rpyOffsets>
        <gaussianNoise>0.01</gaussianNoise>
      </plugin>
      <canonicalBody>${name}_footprint</canonicalBody>
    </gazebo> -->
  <!--    
    <gazebo>
      <plugin name="object_controller" filename="libgazebo_ros_planar_move.so">
        <commandTopic>cmd_vel</commandTopic>
        <odometryTopic>odom_combined</odometryTopic>
        <odometryFrame>odom_combined</odometryFrame>
        <odometryRate>20.0</odometryRate>
        <robotBaseFrame>base_footprint</robotBaseFrame>
      </plugin>
    </gazebo>
    -->
  <gazebo>
    <plugin filename="libhwi_switch_gazebo_ros_control.so" name="ros_control">
      <robotNamespace>base</robotNamespace>
      <filterJointsParam>joint_names</filterJointsParam>
    </plugin>
  </gazebo>
  <!--xacro:tower_asymetric name="tower" parent="base_link">
    <origin xyz="${tower_x} ${tower_y} ${tower_z}" rpy="${tower_roll} ${tower_pitch} ${tower_yaw}" />
  </xacro:tower_asymetric-->
  <joint name="tower_joint" type="fixed">
    <origin rpy="0.0 0.0 3.14159265359" xyz="0.357 0.0 0.306"/>
    <!--origin xyz=" 0.36 -0.029 0.48" rpy="0 0 3.14159265" /-->
    <parent link="base_link"/>
    <child link="tower_base_link"/>
  </joint>
  <link name="tower_base_link">
    <inertial>
      <mass value="6.49"/>
      <origin xyz="0 0 0"/>
      <inertia ixx="0.1" ixy="0.002" ixz="0.01" iyy="0.26" iyz="0.0" izz="0.24"/>
    </inertial>
    <visual>
      <origin rpy="0 0 0" xyz="0 0 0"/>
      <geometry>
        <mesh filename="package://raw_description/meshes/tower/raw_tower_symetric.dae"/>
      </geometry>
    </visual>
    <collision>
      <origin rpy="0 0 0" xyz="0 0 0.0865"/>
      <geometry>
        <!--mesh filename="package://raw_description/meshes/base/raw_tower_collision.stl"/-->
        <box size="0.316 0.573 0.173"/>
      </geometry>
    </collision>
  </link>
  <!-- extensions -->
  <gazebo reference="tower_base_link">
    <gravity>true</gravity>
    <self_collide>false</self_collide>
  </gazebo>
  <!-- joint between base_link and torso_tilt_link -->
  <joint name="torso_0_joint" type="fixed">
    <origin rpy="0.0 0.0 -0.445" xyz="0.166 0.2175 0.5405"/>
    <parent link="base_link"/>
    <child link="torso_0_link"/>
  </joint>
  <link name="torso_0_link">
    <inertial>
      <origin rpy="0 0 0" xyz="0 0 0"/>
      <mass value="0.57307"/>
      <inertia ixx="1.415" ixy="0" ixz="0" iyy="0.819" iyz="0" izz="0.819"/>
    </inertial>
    <visual>
      <origin rpy="0 0 0" xyz="0 0 0"/>
      <geometry>
        <cylinder length="0.521" radius="0.04"/>
      </geometry>
      <material name="IPA/LightGrey"/>
    </visual>
    <collision>
      <origin rpy="0 0 0" xyz="0 0 0"/>
      <geometry>
        <cylinder length="0.521" radius="0.04"/>
      </geometry>
    </collision>
  </link>
  <!-- joint between base_link and torso_lower_neck_tilt_link -->
  <joint name="torso_pan_joint" type="revolute">
    <origin rpy="0.0 0.0 0.0" xyz="0.0 0.0 0.3074"/>
    <parent link="torso_0_link"/>
    <child link="torso_1_link"/>
    <axis xyz="0 0 -1.0"/>
    <dynamics damping="25.0" friction="10.0"/>
    <limit effort="41.4" lower="-6.2831" upper="6.2831" velocity="0.5"/>
  </joint>
  <link name="torso_1_link">
    <inertial>
      <origin rpy="0 0 0" xyz="0 0 0"/>
      <mass value="6.209720"/>
      <inertia ixx="0.171118" ixy="0.002544" ixz="-0.000000" iyy="0.083077" iyz="0.000000" izz="0.120948"/>
    </inertial>
    <visual>
      <origin rpy="3.14 0 0" xyz="0 0 0"/>
      <geometry>
        <cylinder length="0.3" radius="0.15"/>
      </geometry>
      <material name="IPA/LightGrey"/>
    </visual>
    <collision>
      <origin rpy="3.14 0 0" xyz="0 0 0"/>
      <geometry>
        <cylinder length="0.3" radius="0.15"/>
      </geometry>
    </collision>
  </link>
  <!-- joint between torso_upper_neck_tilt_link and head_axis_link -->
  <joint name="torso_tilt_joint" type="revolute">
    <origin rpy="0.0 0.0 0.0" xyz="0.0 0.0 0.047"/>
    <parent link="torso_1_link"/>
    <child link="torso_2_link"/>
    <axis xyz="-1.0 0 0"/>
    <dynamics damping="0.1"/>
    <limit effort="100" lower="-3.2" upper="1.57" velocity="1.4"/>
  </joint>
  <link name="torso_2_link">
    <inertial>
      <origin rpy="0 0 0" xyz="0 0 0"/>
      <mass value="0.1"/>
      <inertia ixx="0.0001" ixy="0" ixz="0" iyy="0.0001" iyz="0" izz="0.0001"/>
    </inertial>
    <visual>
      <origin rpy="0 0 0" xyz="0 0 0"/>
      <geometry>
        <box size="0.01 0.01 0.01"/>
      </geometry>
      <material name="IPA/LightGrey"/>
    </visual>
    <collision>
      <origin rpy="0 0 0" xyz="0 0 0"/>
      <geometry>
        <box size="0.01 0.01 0.01"/>
      </geometry>
    </collision>
  </link>
  <!-- extensions -->
  <gazebo reference="torso_pan_link">
    <gravity>true</gravity>
    <self_collide>false</self_collide>
    <material>IPA/LightGrey</material>
  </gazebo>
  <gazebo reference="torso_tilt_link">
    <gravity>true</gravity>
    <self_collide>false</self_collide>
    <material>IPA/LightGrey</material>
  </gazebo>
  <transmission name="torso_pan_trans">
    <type>transmission_interface/SimpleTransmission</type>
    <joint name="torso_pan_joint">
      <hardwareInterface>PositionJointInterface</hardwareInterface>
    </joint>
    <actuator name="torso_pan_motor">
      <mechanicalReduction>1</mechanicalReduction>
    </actuator>
  </transmission>
  <transmission name="torso_tilt_trans">
    <type>transmission_interface/SimpleTransmission</type>
    <joint name="torso_tilt_joint">
      <hardwareInterface>PositionJointInterface</hardwareInterface>
    </joint>
    <actuator name="torso_tilt_motor">
      <mechanicalReduction>1</mechanicalReduction>
    </actuator>
  </transmission>
  <gazebo>
    <plugin filename="libhwi_switch_gazebo_ros_control.so" name="ros_control">
      <robotNamespace>torso</robotNamespace>
      <filterJointsParam>joint_names</filterJointsParam>
    </plugin>
  </gazebo>
  <!-- joint between torso_2_link and head_base_link -->
  <joint name="head_base_joint" type="fixed">
    <origin rpy="0.0 0.0 0.0" xyz="0.0 0.0 0.0"/>
    <parent link="torso_2_link"/>
    <child link="head_base_link"/>
  </joint>
  <link name="head_base_link"/>
  <!-- joint between head_base_link and head_axis_link -->
  <joint name="head_axis_joint" type="fixed">
    <origin rpy="0 0 0" xyz="0 0 0"/>
    <parent link="head_base_link"/>
    <child link="head_axis_link"/>
  </joint>
  <link name="head_axis_link"/>
  <!--camera reference link-->
  <joint name="head_cam_reference_joint" type="fixed">
    <origin rpy="-1.57 0.0 -1.57" xyz="0.044 0.06 0.092"/>
    <parent link="head_axis_link"/>
    <child link="head_cam_reference_link"/>
  </joint>
  <link name="head_cam_reference_link"/>
  <!-- left camera -->
  <joint name="head_color_camera_l_joint" type="fixed">
    <origin rpy="0.0 0.0 0.0" xyz="0.0 0.0 0.0"/>
    <parent link="head_cam_reference_link"/>
    <child link="head_color_camera_l_link"/>
  </joint>
  <link name="head_color_camera_l_link">
    <inertial>
      <mass value="0.01"/>
      <origin rpy="0 0 0" xyz="0 0 0"/>
      <inertia ixx="0.0001" ixy="0" ixz="0" iyy="0.0001" iyz="0" izz="0.0001"/>
    </inertial>
    <visual>
      <origin rpy="0 0 0" xyz="0 0 0"/>
      <geometry>
        <cylinder length="0.03" radius="0.01"/>
      </geometry>
      <material name="IPA/LightGrey"/>
    </visual>
    <collision>
      <origin rpy="0 0 0" xyz="0 0 0"/>
      <geometry>
        <cylinder length="0.03" radius="0.01"/>
      </geometry>
    </collision>
  </link>
  <joint name="head_color_camera_l_frame_joint" type="fixed">
    <origin rpy="1.57079632679 -1.57079632679 0" xyz="0 0 0"/>
    <parent link="head_color_camera_l_link"/>
    <child link="head_color_camera_l_frame"/>
  </joint>
  <link name="head_color_camera_l_frame"/>
  <gazebo reference="head_color_camera_l_frame">
    <sensor name="head_color_camera_l_sensor" type="camera">
      <always_on>true</always_on>
      <update_rate>10.0</update_rate>
      <camera name="head_color_camera_l_sensor">
        <horizontal_fov>0.58</horizontal_fov>
        <image>
          <format>R8G8B8</format>
          <width>1360</width>
          <height>1024</height>
        </image>
        <clip>
          <near>0.1</near>
          <far>100</far>
        </clip>
        <noise>
          <type>gaussian</type>
          <mean>0.0</mean>
          <stddev>0.0</stddev>
        </noise>
      </camera>
      <plugin filename="libgazebo_ros_camera.so" name="head_color_camera_l_controller">
        <updateRate>10.0</updateRate>
        <cameraName>head_color_camera_l_sensor</cameraName>
        <frameName>/head_color_camera_l_link</frameName>
        <topicName>stereo/left_image_data</topicName>
        <imageTopicName>/stereo/left/image_raw</imageTopicName>
        <cameraInfoTopicName>/stereo/left/camera_info</cameraInfoTopicName>
        <pollServiceName>/head_color_camera_l/request_image</pollServiceName>
        <CxPrime>697.69</CxPrime>
        <Cx>697.69</Cx>
        <Cy>530.51</Cy>
        <focalLength>2278.722731</focalLength>
        <!-- focal_length = width_ / (2.0 * tan( HFOV/2.0 )) -->
        <hackBaseline>0.0</hackBaseline>
        <distortionK1>0.0</distortionK1>
        <distortionK2>0.0</distortionK2>
        <distortionK3>0.0</distortionK3>
        <distortionT1>0.0</distortionT1>
        <distortionT2>0.0</distortionT2>
      </plugin>
    </sensor>
    <material value="IPA/LightGrey"/>
  </gazebo>
  <!-- right camera -->
  <joint name="head_color_camera_r_joint" type="fixed">
    <origin rpy="0.0 0.0 0.0" xyz="0.12 0.0 0.0"/>
    <parent link="head_cam_reference_link"/>
    <child link="head_color_camera_r_link"/>
  </joint>
  <link name="head_color_camera_r_link">
    <inertial>
      <mass value="0.01"/>
      <origin rpy="0 0 0" xyz="0 0 0"/>
      <inertia ixx="0.0001" ixy="0" ixz="0" iyy="0.0001" iyz="0" izz="0.0001"/>
    </inertial>
    <visual>
      <origin rpy="0 0 0" xyz="0 0 0"/>
      <geometry>
        <cylinder length="0.03" radius="0.01"/>
      </geometry>
      <material name="IPA/LightGrey"/>
    </visual>
    <collision>
      <origin rpy="0 0 0" xyz="0 0 0"/>
      <geometry>
        <cylinder length="0.03" radius="0.01"/>
      </geometry>
    </collision>
  </link>
  <joint name="head_color_camera_r_frame_joint" type="fixed">
    <origin rpy="1.57079632679 -1.57079632679 0" xyz="0 0 0"/>
    <parent link="head_color_camera_r_link"/>
    <child link="head_color_camera_r_frame"/>
  </joint>
  <link name="head_color_camera_r_frame"/>
  <gazebo reference="head_color_camera_r_frame">
    <sensor name="head_color_camera_r_sensor" type="camera">
      <always_on>true</always_on>
      <update_rate>10.0</update_rate>
      <camera name="head_color_camera_r_sensor">
        <horizontal_fov>0.58</horizontal_fov>
        <image>
          <format>R8G8B8</format>
          <width>1360</width>
          <height>1024</height>
        </image>
        <clip>
          <near>0.1</near>
          <far>100</far>
        </clip>
        <noise>
          <type>gaussian</type>
          <mean>0.0</mean>
          <stddev>0.0</stddev>
        </noise>
      </camera>
      <plugin filename="libgazebo_ros_camera.so" name="head_color_camera_r_controller">
        <updateRate>10.0</updateRate>
        <cameraName>head_color_camera_r_sensor</cameraName>
        <frameName>/head_color_camera_r_link</frameName>
        <topicName>stereo/right_image_data</topicName>
        <imageTopicName>/stereo/right/image_raw</imageTopicName>
        <cameraInfoTopicName>/stereo/right/camera_info</cameraInfoTopicName>
        <pollServiceName>/head_color_camera_r/request_image</pollServiceName>
        <CxPrime>697.69</CxPrime>
        <Cx>697.69</Cx>
        <Cy>530.51</Cy>
        <focalLength>2278.722731</focalLength>
        <!-- focal_length = width_ / (2.0 * tan( HFOV/2.0 )) -->
        <hackBaseline>0.0</hackBaseline>
        <distortionK1>0.0</distortionK1>
        <distortionK2>0.0</distortionK2>
        <distortionK3>0.0</distortionK3>
        <distortionT1>0.0</distortionT1>
        <distortionT2>0.0</distortionT2>
      </plugin>
    </sensor>
    <material value="IPA/LightGrey"/>
  </gazebo>
  <!-- cam3d -->
  <joint name="head_cam3d_joint" type="fixed">
    <origin rpy="0.0 0.0 0.0" xyz="0.06 0.0 0.0"/>
    <parent link="head_cam_reference_link"/>
    <child link="head_cam3d_link"/>
  </joint>
  <link name="head_cam3d_link">
    <inertial>
      <mass value="0.3"/>
      <origin rpy="0 0 0" xyz="0 0 0"/>
      <inertia ixx="9.312496275e-05" ixy="0.0" ixz="0.0" iyy="0.000872499651" iyz="0.0" izz="0.00084062466375"/>
    </inertial>
    <visual>
      <origin rpy="0 0 0" xyz="0 0 -0.03"/>
      <geometry>
        <box size="0.02 0.02 0.02"/>
      </geometry>
      <material name="IPA/LightGrey"/>
    </visual>
    <collision>
      <origin rpy="0 0 0" xyz="0 0 -0.03"/>
      <geometry>
        <box size="0.02 0.02 0.02"/>
      </geometry>
    </collision>
  </link>
  <joint name="head_cam3d_frame_joint" type="fixed">
    <origin rpy="1.57079632679 -1.57079632679 0" xyz="0 0 0"/>
    <parent link="head_cam3d_link"/>
    <child link="head_cam3d_frame"/>
  </joint>
  <link name="head_cam3d_frame"/>
  <!-- extensions -->
  <gazebo reference="head_cam3d_frame">
    <sensor name="head_cam3d_frame_sensor" type="depth">
      <always_on>true</always_on>
      <update_rate>20.0</update_rate>
      <camera>
        <horizontal_fov>1.08210413624</horizontal_fov>
        <image>
          <format>R8G8B8</format>
          <width>640</width>
          <height>480</height>
        </image>
        <clip>
          <near>0.1</near>
          <far>100</far>
        </clip>
        <noise>
          <type>gaussian</type>
          <mean>0.0</mean>
          <stddev>0.0</stddev>
        </noise>
      </camera>
      <plugin filename="libgazebo_ros_openni_kinect.so" name="head_cam3d_controller">
        <updateRate>20.0</updateRate>
        <cameraName>cam3d</cameraName>
        <frameName>head_cam3d_link</frameName>
        <imageTopicName>rgb/image_raw</imageTopicName>
        <cameraInfoTopicName>rgb/camera_info</cameraInfoTopicName>
        <pointCloudTopicName>depth_registered/points</pointCloudTopicName>
        <depthImageTopicName>depth_registered/image_raw</depthImageTopicName>
        <depthImageCameraInfoTopicName>depth_registered/camera_info</depthImageCameraInfoTopicName>
        <pointCloudCutoff>0.5</pointCloudCutoff>
        <pointCloudCutoffMax>5.0</pointCloudCutoffMax>
        <baseline>0.2</baseline>
        <hackBaseline>0.0</hackBaseline>
        <distortionK1>0.0</distortionK1>
        <distortionK2>0.0</distortionK2>
        <distortionK3>0.0</distortionK3>
        <distortionT1>0.0</distortionT1>
        <distortionT2>0.0</distortionT2>
        <CxPrime>0.0</CxPrime>
        <Cx>0.0</Cx>
        <Cy>0.0</Cy>
        <focalLength>0.0</focalLength>
      </plugin>
    </sensor>
    <material>IPA/LightGrey</material>
  </gazebo>
  <!-- mount the arm to the robot -->
  <joint name="arm_base_joint" type="fixed">
    <origin rpy="0.0 0.0 -2.3562" xyz="0.324 -0.191 0.585"/>
    <parent link="base_link"/>
    <child link="arm_base_link"/>
  </joint>
  <!-- include universal_robot arm -->
  <link name="arm_base_link">
    <visual>
      <geometry>
        <mesh filename="package://ur_description/meshes/ur10/visual/base.dae"/>
      </geometry>
      <material name="LightGrey">
        <color rgba="0.7 0.7 0.7 1.0"/>
      </material>
    </visual>
    <collision>
      <geometry>
        <mesh filename="package://ur_description/meshes/ur10/collision/base.stl"/>
      </geometry>
    </collision>
    <inertial>
      <mass value="0.4"/>
      <origin rpy="0 0 0" xyz="0.0 0.0 0.0"/>
      <inertia ixx="0.00061063308908" ixy="0.0" ixz="0.0" iyy="0.00061063308908" iyz="0.0" izz="0.001125"/>
    </inertial>
  </link>
  <joint name="arm_shoulder_pan_joint" type="revolute">
    <parent link="arm_base_link"/>
    <child link="arm_shoulder_link"/>
    <origin rpy="0.0 0.0 0.0" xyz="0.0 0.0 0.1273"/>
    <axis xyz="0 0 1"/>
    <limit effort="330.0" lower="-3.14159265" upper="3.14159265" velocity="2.16"/>
    <dynamics damping="0.0" friction="0.0"/>
  </joint>
  <link name="arm_shoulder_link">
    <visual>
      <geometry>
        <mesh filename="package://ur_description/meshes/ur10/visual/shoulder.dae"/>
      </geometry>
      <material name="LightGrey">
        <color rgba="0.7 0.7 0.7 1.0"/>
      </material>
    </visual>
    <collision>
      <geometry>
        <mesh filename="package://ur_description/meshes/ur10/collision/shoulder.stl"/>
      </geometry>
    </collision>
    <inertial>
      <mass value="0.7778"/>
      <origin rpy="0 0 0" xyz="0.0 0.0 0.0"/>
      <inertia ixx="0.00314743125769" ixy="0.0" ixz="0.0" iyy="0.00314743125769" iyz="0.0" izz="0.0021875625"/>
    </inertial>
  </link>
  <joint name="arm_shoulder_lift_joint" type="revolute">
    <parent link="arm_shoulder_link"/>
    <child link="arm_upper_arm_link"/>
    <origin rpy="0.0 1.570796325 0.0" xyz="0.0 0.220941 0.0"/>
    <axis xyz="0 1 0"/>
    <limit effort="330.0" lower="-3.14159265" upper="3.14159265" velocity="2.16"/>
    <dynamics damping="0.0" friction="0.0"/>
  </joint>
  <link name="arm_upper_arm_link">
    <visual>
      <geometry>
        <mesh filename="package://ur_description/meshes/ur10/visual/upperarm.dae"/>
      </geometry>
      <material name="LightGrey">
        <color rgba="0.7 0.7 0.7 1.0"/>
      </material>
    </visual>
    <collision>
      <geometry>
        <mesh filename="package://ur_description/meshes/ur10/collision/upperarm.stl"/>
      </geometry>
    </collision>
    <inertial>
      <mass value="0.1293"/>
      <origin rpy="0 0 0" xyz="0.0 0.0 0.306"/>
      <inertia ixx="0.00421753803798" ixy="0.0" ixz="0.0" iyy="0.00421753803798" iyz="0.0" izz="0.00036365625"/>
    </inertial>
  </link>
  <joint name="arm_elbow_joint" type="revolute">
    <parent link="arm_upper_arm_link"/>
    <child link="arm_forearm_link"/>
    <origin rpy="0.0 0.0 0.0" xyz="0.0 -0.1719 0.612"/>
    <axis xyz="0 1 0"/>
    <limit effort="150.0" lower="-3.14159265" upper="3.14159265" velocity="3.15"/>
    <dynamics damping="0.0" friction="0.0"/>
  </joint>
  <link name="arm_forearm_link">
    <visual>
      <geometry>
        <mesh filename="package://ur_description/meshes/ur10/visual/forearm.dae"/>
      </geometry>
      <material name="LightGrey">
        <color rgba="0.7 0.7 0.7 1.0"/>
      </material>
    </visual>
    <collision>
      <geometry>
        <mesh filename="package://ur_description/meshes/ur10/collision/forearm.stl"/>
      </geometry>
    </collision>
    <inertial>
      <mass value="0.387"/>
      <origin rpy="0 0 0" xyz="0.0 0.0 0.28615"/>
      <inertia ixx="0.0111069694097" ixy="0.0" ixz="0.0" iyy="0.0111069694097" iyz="0.0" izz="0.0010884375"/>
    </inertial>
  </link>
  <joint name="arm_wrist_1_joint" type="revolute">
    <parent link="arm_forearm_link"/>
    <child link="arm_wrist_1_link"/>
    <origin rpy="0.0 1.570796325 0.0" xyz="0.0 0.0 0.5723"/>
    <axis xyz="0 1 0"/>
    <limit effort="54.0" lower="-3.14159265" upper="3.14159265" velocity="3.2"/>
    <dynamics damping="0.0" friction="0.0"/>
  </joint>
  <link name="arm_wrist_1_link">
    <visual>
      <geometry>
        <mesh filename="package://ur_description/meshes/ur10/visual/wrist1.dae"/>
      </geometry>
      <material name="LightGrey">
        <color rgba="0.7 0.7 0.7 1.0"/>
      </material>
    </visual>
    <collision>
      <geometry>
        <mesh filename="package://ur_description/meshes/ur10/collision/wrist1.stl"/>
      </geometry>
    </collision>
    <inertial>
      <mass value="0.196"/>
      <origin rpy="0 0 0" xyz="0.0 0.0 0.0"/>
      <inertia ixx="0.00051082479567" ixy="0.0" ixz="0.0" iyy="0.00051082479567" iyz="0.0" izz="0.00055125"/>
    </inertial>
  </link>
  <joint name="arm_wrist_2_joint" type="revolute">
    <parent link="arm_wrist_1_link"/>
    <child link="arm_wrist_2_link"/>
    <origin rpy="0.0 0.0 0.0" xyz="0.0 0.1149 0.0"/>
    <axis xyz="0 0 1"/>
    <limit effort="54.0" lower="-3.14159265" upper="3.14159265" velocity="3.2"/>
    <dynamics damping="0.0" friction="0.0"/>
  </joint>
  <link name="arm_wrist_2_link">
    <visual>
      <geometry>
        <mesh filename="package://ur_description/meshes/ur10/visual/wrist2.dae"/>
      </geometry>
      <material name="LightGrey">
        <color rgba="0.7 0.7 0.7 1.0"/>
      </material>
    </visual>
    <collision>
      <geometry>
        <mesh filename="package://ur_description/meshes/ur10/collision/wrist2.stl"/>
      </geometry>
    </collision>
    <inertial>
      <mass value="0.196"/>
      <origin rpy="0 0 0" xyz="0.0 0.0 0.0"/>
      <inertia ixx="0.00051082479567" ixy="0.0" ixz="0.0" iyy="0.00051082479567" iyz="0.0" izz="0.00055125"/>
    </inertial>
  </link>
  <joint name="arm_wrist_3_joint" type="revolute">
    <parent link="arm_wrist_2_link"/>
    <child link="arm_wrist_3_link"/>
    <origin rpy="0.0 0.0 0.0" xyz="0.0 0.0 0.1157"/>
    <axis xyz="0 1 0"/>
    <limit effort="54.0" lower="-3.14159265" upper="3.14159265" velocity="3.2"/>
    <dynamics damping="0.0" friction="0.0"/>
  </joint>
  <link name="arm_wrist_3_link">
    <visual>
      <geometry>
        <mesh filename="package://ur_description/meshes/ur10/visual/wrist3.dae"/>
      </geometry>
      <material name="LightGrey">
        <color rgba="0.7 0.7 0.7 1.0"/>
      </material>
    </visual>
    <collision>
      <geometry>
        <mesh filename="package://ur_description/meshes/ur10/collision/wrist3.stl"/>
      </geometry>
    </collision>
    <inertial>
      <mass value="0.0202"/>
      <origin rpy="0 0 0" xyz="0.0 0.0 0.0"/>
      <inertia ixx="5.26462289415e-05" ixy="0.0" ixz="0.0" iyy="5.26462289415e-05" iyz="0.0" izz="5.68125e-05"/>
    </inertial>
  </link>
  <joint name="arm_ee_fixed_joint" type="fixed">
    <parent link="arm_wrist_3_link"/>
    <child link="arm_ee_link"/>
    <origin rpy="0.0 0.0 1.570796325" xyz="0.0 0.0922 0.0"/>
  </joint>
  <link name="arm_ee_link">
    <collision>
      <geometry>
        <box size="0.01 0.01 0.01"/>
      </geometry>
      <origin rpy="0 0 0" xyz="-0.01 0 0"/>
    </collision>
  </link>
  <transmission name="arm_shoulder_pan_trans">
    <type>transmission_interface/SimpleTransmission</type>
    <joint name="arm_shoulder_pan_joint">
      <hardwareInterface>PositionJointInterface</hardwareInterface>
      <hardwareInterface>VelocityJointInterface</hardwareInterface>
    </joint>
    <actuator name="arm_shoulder_pan_motor">
      <mechanicalReduction>1</mechanicalReduction>
    </actuator>
  </transmission>
  <transmission name="arm_shoulder_lift_trans">
    <type>transmission_interface/SimpleTransmission</type>
    <joint name="arm_shoulder_lift_joint">
      <hardwareInterface>PositionJointInterface</hardwareInterface>
      <hardwareInterface>VelocityJointInterface</hardwareInterface>
    </joint>
    <actuator name="arm_shoulder_lift_motor">
      <mechanicalReduction>1</mechanicalReduction>
    </actuator>
  </transmission>
  <transmission name="arm_elbow_trans">
    <type>transmission_interface/SimpleTransmission</type>
    <joint name="arm_elbow_joint">
      <hardwareInterface>PositionJointInterface</hardwareInterface>
      <hardwareInterface>VelocityJointInterface</hardwareInterface>
    </joint>
    <actuator name="arm_elbow_motor">
      <mechanicalReduction>1</mechanicalReduction>
    </actuator>
  </transmission>
  <transmission name="arm_wrist_1_trans">
    <type>transmission_interface/SimpleTransmission</type>
    <joint name="arm_wrist_1_joint">
      <hardwareInterface>PositionJointInterface</hardwareInterface>
      <hardwareInterface>VelocityJointInterface</hardwareInterface>
    </joint>
    <actuator name="arm_wrist_1_motor">
      <mechanicalReduction>1</mechanicalReduction>
    </actuator>
  </transmission>
  <transmission name="arm_wrist_2_trans">
    <type>transmission_interface/SimpleTransmission</type>
    <joint name="arm_wrist_2_joint">
      <hardwareInterface>PositionJointInterface</hardwareInterface>
      <hardwareInterface>VelocityJointInterface</hardwareInterface>
    </joint>
    <actuator name="arm_wrist_2_motor">
      <mechanicalReduction>1</mechanicalReduction>
    </actuator>
  </transmission>
  <transmission name="arm_wrist_3_trans">
    <type>transmission_interface/SimpleTransmission</type>
    <joint name="arm_wrist_3_joint">
      <hardwareInterface>PositionJointInterface</hardwareInterface>
      <hardwareInterface>VelocityJointInterface</hardwareInterface>
    </joint>
    <actuator name="arm_wrist_3_motor">
      <mechanicalReduction>1</mechanicalReduction>
    </actuator>
  </transmission>
  <!-- nothing to do here at the moment -->
  <!-- ROS base_link to UR 'Base' Coordinates transform 
    <link name="${prefix}base"/>
    <joint name="${prefix}base_link-base_fixed_joint" type="fixed">-->
  <!-- NOTE: this rotation is only needed as long as base_link itself is
                 not corrected wrt the real robot (ie: rotated over 180
                 degrees)
      -->
  <!--   <origin xyz="0 0 0" rpy="0 0 ${-pi}"/>
      <parent link="${prefix}base_link"/>
      <child link="${prefix}base"/>
    </joint>-->
  <!-- Frame coincident with all-zeros TCP on UR controller -->
  <link name="arm_tool0"/>
  <joint name="arm_wrist_3_link-tool0_fixed_joint" type="fixed">
    <origin rpy="-1.570796325 0 0" xyz="0 0.0922 0"/>
    <parent link="arm_wrist_3_link"/>
    <child link="arm_tool0"/>
  </joint>
  <gazebo>
    <plugin filename="libhwi_switch_gazebo_ros_control.so" name="ros_control">
      <robotNamespace>arm</robotNamespace>
      <filterJointsParam>joint_names</filterJointsParam>
    </plugin>
  </gazebo>
  <!--xacro:raw_boxgripper name="gripper" parent="arm_ee_link">
    <origin xyz="${gripper_x} ${gripper_y} ${gripper_z}" rpy="${gripper_roll} ${gripper_pitch} ${gripper_yaw}" />
  </xacro:raw_boxgripper> -->
  <!-- arm-gripper coupling joint definitions 
	<joint name="${arm_prefix}to_gripper" type="fixed">
		<parent link="arm_ee_link"/>
		<child link="${arm_prefix}gripper_frame"/>
		<origin xyz="0 0 0" rpy="-1.57 0 -1.57"/> 
	</joint>-->
  <!-- joint between arm_ee_link and raw_boxgripper_link -->
  <joint name="gripper_base_joint" type="fixed">
    <origin rpy="0 0 0" xyz="0.0 0.0 0.0"/>
    <parent link="arm_ee_link"/>
    <child link="arm_gripper_frame"/>
  </joint>
  <link name="arm_gripper_frame"/>
  <joint name="arm_gripper_to_palm" type="fixed">
    <parent link="arm_gripper_frame"/>
    <child link="arm_gripper_body"/>
    <origin rpy="1.57079632679 0 3.1415" xyz="0.08015 0.0475 0.0"/>
  </joint>
  <link name="arm_gripper_body">
    <visual>
      <!--origin xyz="0 0.036 -0.0473" rpy="0 0 0"/-->
      <!--geometry>
					<box size="${gripper_length} ${gripper_width} ${gripper_height}"/>
				</geometry-->
      <origin rpy="0 0 0" xyz="0 0 -0.048"/>
      <geometry>
        <mesh filename="package://raw_description/meshes/vacuum_gripper/Segmentgreifer_2.STL"/>
      </geometry>
      <material name="silver">
        <color rgba="0.8 0.8 0.8 1"/>
      </material>
    </visual>
    <collision>
      <origin xyz="0 0.03 -0.05"/>
      <geometry>
        <box size="0.13 0.17 0.11"/>
      </geometry>
      <material name="another_blue2">
        <color rgba="0.38 0.54 0.83 1"/>
      </material>
    </collision>
  </link>
  <joint name="arm_gripper_to_tcp" type="fixed">
    <parent link="arm_gripper_frame"/>
    <child link="gripper"/>
    <origin rpy="0 0 0" xyz=" 0.1263 0.0 0.0"/>
  </joint>
  <link name="gripper">
    <visual>
      <geometry>
        <sphere radius="0.005"/>
      </geometry>
      <material name="white">
        <color rgba="1 1 1 0.5"/>
      </material>
    </visual>
    <collision>
      <geometry>
        <sphere radius="0.005"/>
      </geometry>
    </collision>
  </link>
  <!-- extensions -->
  <gazebo reference="gripper_ee_link">
    <gravity>true</gravity>
    <self_collide>false</self_collide>
  </gazebo>
  <!-- IMU brick mount on raw3-1 
  <joint name="imu_brick_joint" type="fixed" >
    <origin xyz="0.402 -0.0811 0.335" rpy="0 0 0" />
    <parent link="base_link" />
    <child link="imu_brick_link" />
  </joint>

  <link name="imu_brick_link">
    <xacro:default_inertial />
    <visual>
      <origin xyz="0 0 -0.02" rpy="0 0 0" />
      <geometry>
        <box size="0.04 0.04 0.02" />
      </geometry>
      <material name="IPA/LightGrey" />
    </visual>
  </link>-->
  <!-- END: IMU brick  mount -->
  <!-- rfid_front mount on raw3-1 -->
  <!--joint name="rfid_front_joint" type="fixed" >
    <origin xyz="0.55128 0.0 0.09" rpy="0 0 0" />
    <parent link="base_link" />
    <child link="rfid_front_link" />
  </joint>

  <link name="rfid_front_link">
    <xacro:default_inertial />
    <visual>
      <origin xyz="0 0 0" rpy="0 0 0" />
      <geometry>
        <box size="0.16 0.36 0.09" />
      </geometry>
      <material name="blue">
        <color rgba="0 0 .8 1"/>
      </material>
    </visual>
  </link-->
  <!-- END: rfid front mount -->
  <!-- rfid_rear mount on raw3-1 -->
  <!--joint name="rfid_rear_joint" type="fixed" >
    <origin xyz="-0.55128 0.0 0.09" rpy="0 0 ${M_PI}" />
    <parent link="base_link" />
    <child link="rfid_rear_link" />
  </joint>

  <link name="rfid_rear_link">
    <xacro:default_inertial />
    <visual>
      <origin xyz="0 0 0" rpy="0 0 0" />
      <geometry>
        <box size="0.16 0.36 0.09" />
      </geometry>
      <material name="blue">
        <color rgba="0 0 .8 1"/>
      </material>
    </visual>
  </link-->
  <!-- END: rfid rear mount -->
  <!-- rfid_right mount on raw3-1 -->
  <!--joint name="rfid_right_joint" type="fixed" >
    <origin xyz="0.0 -0.30850 0.09" rpy="0 0 ${-0.5*M_PI}" />
    <parent link="base_link" />
    <child link="rfid_right_link" />
  </joint>

  <link name="rfid_right_link">
    <xacro:default_inertial />
    <visual>
      <origin xyz="0 0 0" rpy="0 0 0" />
      <geometry>
        <box size="0.16 0.36 0.09" />
      </geometry>
      <material name="blue">
        <color rgba="0 0 .8 1"/>
      </material>
    </visual>
  </link-->
  <!-- END: rfid right mount -->
  <!-- Camera pillar -->
  <!--joint name="camera_pillar_joint" type="fixed" >
    <origin xyz="0.4925 0.0825 0.48" rpy="0 0 0" />
    <parent link="base_link" />
    <child link="camera_pillar_link" />
  </joint>

  <link name="camera_pillar_link">
    <xacro:default_inertial />
    <visual>
      <origin xyz="0 0 0.123" rpy="0 0 0" />
      <geometry>
        <box size="0.045 0.045 0.246" />
      </geometry>
      <material name="IPA/LightGrey" />
    </visual>
  </link-->
  <!-- END: camera_pillar -->
  <!-- Softkinetic 'left' mount on raw3-1 -->
  <!--joint name="softkinetic_left_joint" type="fixed" >
    <origin xyz="0.015 0.06 0.215" rpy="0.0 ${M_PI/2} 0.0" />
    <parent link="camera_pillar_link" />
    <child link="softkinetic_left_link" />
  </joint>

  <link name="softkinetic_left_link">
    <xacro:default_inertial />
    <visual>
      <origin xyz="0.0 0.0 0.0" rpy="0.0 0.0 0.0" />
      <geometry>
        <box size="0.10 0.03 0.03" />
      </geometry>
      <material name="IPA/Black" />
    </visual>
  </link-->
  <!-- END: Softkinetic 'left' mount -->
  <!-- Softkinetic 'right' mount on raw3-1 -->
  <!--joint name="softkinetic_right_joint" type="fixed" >
    <origin xyz="0.015 -0.06 0.215" rpy="${M_PI} -${M_PI/2} 0.0" />
    <parent link="camera_pillar_link" />
    <child link="softkinetic_right_link" />
  </joint>

  <link name="softkinetic_right_link">
    <xacro:default_inertial />
    <visual>
      <origin xyz="0.0 0.0 0.0" rpy="0.0 0.0 0.0" />
      <geometry>
        <box size="0.10 0.03 0.03" />
      </geometry>
      <material name="IPA/Black" />
    </visual>
  </link-->
  <!-- END: Softkinetic 'right' mount -->
  <!-- Kinect mount on raw3-1 -->
  <!--joint name="kinect_joint" type="fixed" >
    <origin xyz="0.015 0.0 0.25" rpy="${M_PI/2} 0 ${M_PI/2}" />
    <parent link="camera_pillar_link" />
    <child link="kinect_link" />
  </joint>

  <link name="kinect_link">
    <xacro:default_inertial />
    <visual>
      <origin xyz="0.0 0.0 0.0" rpy="0.0 0.0 0.0" />
      <geometry>
        <box size="0.10 0.03 0.03" />
      </geometry>
      <material name="IPA/Black" />
    </visual>
  </link-->
  <!-- END: Kinect mount -->
</robot>
